Workbook

Sheet LEEME
A2: Modelo de compras y costes de producto de gazpacho
A3: Modelo anual para 2026 | EUR | kg y litros
A6: Objetivo de negocio
A7: Conectar el plan anual de producción con la receta, las necesidades de materias primas, las compras, los costes, el control de merma y los KPI de gestión.
A9: Funcionamiento del modelo
A10: Plan de producción → Receta/lista de materiales → Necesidades de materias primas → Compras → Precios de compra → Gasto de materias primas → Coste de producto → Control de merma → KPI
A12: Principales supuestos
A13: Año del modelo 2026. Escenario anual de producción de referencia: 1.200.000 L. Plan de enero: 100.000 L. Densidad: 1,00 kg/L. Unidad de compra: kg. Dos lotes de compra. Umbral de alerta de merma: 1,00%.
A16: Datos maestros y datos transaccionales
A17: Maestro_Ingredientes contiene la receta editable y los supuestos de merma esperada. Plan_Produccion, Plan_Compras y los campos manuales de Modelo_Costes contienen los datos transaccionales mensuales.
A20: Compra requerida y compra real
A21: La compra requerida es la cantidad bruta de ingrediente derivada de la producción y de la merma esperada. La compra real es la cantidad total introducida en un máximo de dos lotes de compra mensuales.
... A42: Este modelo de porfolio es ficticio y se ha creado con fines educativos. No contiene ni implica datos reales de operaciones, precios, costes, volúmenes, compras ni información confidencial de AMC Fresh, Lidl o ninguna otra empresa.

Sheet Supuestos
A2: Supuestos
A3: Modelo anual para 2026 | EUR | kg y litros
A6: Parámetro | B6: Valor | C6: Unidad | D6: Tipo de entrada | E6: Notas
A7: Año del modelo | B7: 2026 | C7: año | D7: Manual | E7: Año natural
A8: Escenario estimado de producción anual | B8: 1200000 | C8: L | D8: Manual | E8: Solo como referencia. No completa los meses futuros
A9: Densidad del producto terminado | B9: 1 | C9: kg/L | D9: Manual | E9: Se utiliza para convertir el porcentaje de receta en kg/L netos
A10: Moneda | B10: EUR | C10: código | D10: Manual | E10: Moneda de presentación del modelo
A11: Unidad de compra | B11: kg | C11: UdM | D11: Manual | E11: Unidad utilizada para todas las cantidades de compra
A12: Máximo de lotes de compra por ingrediente y mes | B12: 2 | C12: lotes | D12: Manual | E12: El Plan de compras permite dos lotes
A13: Umbral de alerta de desviación de merma | B13: 0.01 | C13: % de la producción | D13: Manual | E13: Umbral mensual de desviación absoluta de merma
A16: Convenciones del libro
A18: Celdas amarillas | B18: Entradas manuales
A19: Celdas gris claro | B19: Campos calculados
A20: Celdas azul claro | B20: KPI y resultados
A21: Celdas o texto rojos | B21: Alertas o controles fallidos

Sheet Maestro_Ingredientes
A2: Maestro de ingredientes y receta/lista de materiales
A3: Modelo anual para 2026 | EUR | kg y litros
A6: ID de ingrediente | B6: Ingrediente | C6: Categoría | D6: Unidad de compra | E6: % de receta | F6: % de merma esperada | G6: kg/L netos | H6: kg/L brutos | I6: Activo
A7: ING-001 | B7: Tomate pera | C7: Hortalizas frescas | D7: kg | E7: 0.703 | F7: 0.08 | G7: =Supuestos!$B$9*E7 -> 0.703 | H7: =G7/(1-F7) -> 0.76413043 | I7: Sí
A8: ING-002 | B8: Pepino | C8: Hortalizas frescas | D8: kg | E8: 0.122 | F8: 0.12 | G8: =Supuestos!$B$9*E8 -> 0.122 | H8: =G8/(1-F8) -> 0.13863636 | I8: Sí
A9: ING-003 | B9: Pimiento verde | C9: Hortalizas frescas | D9: kg | E9: 0.073 | F9: 0.15 | G9: =Supuestos!$B$9*E9 -> 0.073 | H9: =G9/(1-F9) -> 0.085882353 | I9: Sí
A10: ING-004 | B10: Cebolla | C10: Hortalizas frescas | D10: kg | E10: 0.044 | F10: 0.1 | G10: =Supuestos!$B$9*E10 -> 0.044 | H10: =G10/(1-F10) -> 0.048888889 | I10: Sí
A11: ING-005 | B11: Ajo | C11: Hortalizas frescas | D11: kg | E11: 0.008 | F11: 0.08 | G11: =Supuestos!$B$9*E11 -> 0.008 | H11: =G11/(1-F11) -> 0.0086956522 | I11: Sí
A12: ING-006 | B12: Aceite de oliva virgen extra | C12: Aceite | D12: kg | E12: 0.026 | F12: 0.005 | G12: =Supuestos!$B$9*E12 -> 0.026 | H12: =G12/(1-F12) -> 0.026130653 | I12: Sí
A13: ING-007 | B13: Vinagre de Jerez | C13: Ácidos y condimentos | D13: kg | E13: 0.013 | F13: 0.005 | G13: =Supuestos!$B$9*E13 -> 0.013 | H13: =G13/(1-F13) -> 0.013065327 | I13: Sí
A14: ING-008 | B14: Sal | C14: Condimentos | D14: kg | E14: 0.007 | F14: 0 | G14: =Supuestos!$B$9*E14 -> 0.007 | H14: =G14/(1-F14) -> 0.007 | I14: Sí
A15: ING-009 | B15: Zumo de limón | C15: Ácidos y condimentos | D15: kg | E15: 0.004 | F15: 0.02 | G15: =Supuestos!$B$9*E15 -> 0.004 | H15: =G15/(1-F15) -> 0.0040816327 | I15: Sí
A18: Control de receta
A20: Total de la receta | B20: =SUM(E7:E15) -> 1 | D20: Supuestos de un ejercicio ficticio. La receta y los porcentajes de merma esperada son editables.
A21: Estado del control | B21: =IF(ABS(B20-1)<0.0000001,"OK","ALERTA – LA RECETA NO SUMA EL 100%") -> OK

Sheet Plan_Produccion
A2: Plan de producción y necesidades de materias primas
A3: Modelo anual para 2026 | EUR | kg y litros
A6: Mes | B6: Producción planificada L | C6: Necesidad neta kg | D6: Compra requerida kg | E6: Merma esperada kg | F6: Estado de la entrada
A7: 46023 | B7: 100000 | C7: =IF(B7="","",B7*SUM(Maestro_Ingredientes!$G$7:$G$15)) -> 100000 | D7: =IF(B7="","",B7*SUM(Maestro_Ingredientes!$H$7:$H$15)) -> 109651.13 | E7: =IF(B7="","",D7-C7) -> 9651.1305 | F7: =IF(B7="","","Introducida") -> Introducida
A8: 46054 | C8: =IF(B8="","",B8*SUM(Maestro_Ingredientes!$G$7:$G$15)) | D8: =IF(B8="","",B8*SUM(Maestro_Ingredientes!$H$7:$H$15)) | E8: =IF(B8="","",D8-C8) | F8: =IF(B8="","","Introducida")
A9: 46082 | C9: =IF(B9="","",B9*SUM(Maestro_Ingredientes!$G$7:$G$15)) | D9: =IF(B9="","",B9*SUM(Maestro_Ingredientes!$H$7:$H$15)) | E9: =IF(B9="","",D9-C9) | F9: =IF(B9="","","Introducida")
A10: 46113 | C10: =IF(B10="","",B10*SUM(Maestro_Ingredientes!$G$7:$G$15)) | D10: =IF(B10="","",B10*SUM(Maestro_Ingredientes!$H$7:$H$15)) | E10: =IF(B10="","",D10-C10) | F10: =IF(B10="","","Introducida")
A11: 46143 | C11: =IF(B11="","",B11*SUM(Maestro_Ingredientes!$G$7:$G$15)) | D11: =IF(B11="","",B11*SUM(Maestro_Ingredientes!$H$7:$H$15)) | E11: =IF(B11="","",D11-C11) | F11: =IF(B11="","","Introducida")
A12: 46174 | C12: =IF(B12="","",B12*SUM(Maestro_Ingredientes!$G$7:$G$15)) | D12: =IF(B12="","",B12*SUM(Maestro_Ingredientes!$H$7:$H$15)) | E12: =IF(B12="","",D12-C12) | F12: =IF(B12="","","Introducida")
A13: 46204 | C13: =IF(B13="","",B13*SUM(Maestro_Ingredientes!$G$7:$G$15)) | D13: =IF(B13="","",B13*SUM(Maestro_Ingredientes!$H$7:$H$15)) | E13: =IF(B13="","",D13-C13) | F13: =IF(B13="","","Introducida")
A14: 46235 | C14: =IF(B14="","",B14*SUM(Maestro_Ingredientes!$G$7:$G$15)) | D14: =IF(B14="","",B14*SUM(Maestro_Ingredientes!$H$7:$H$15)) | E14: =IF(B14="","",D14-C14) | F14: =IF(B14="","","Introducida")
A15: 46266 | C15: =IF(B15="","",B15*SUM(Maestro_Ingredientes!$G$7:$G$15)) | D15: =IF(B15="","",B15*SUM(Maestro_Ingredientes!$H$7:$H$15)) | E15: =IF(B15="","",D15-C15) | F15: =IF(B15="","","Introducida")
A16: 46296 | C16: =IF(B16="","",B16*SUM(Maestro_Ingredientes!$G$7:$G$15)) | D16: =IF(B16="","",B16*SUM(Maestro_Ingredientes!$H$7:$H$15)) | E16: =IF(B16="","",D16-C16) | F16: =IF(B16="","","Introducida")
A17: 46327 | C17: =IF(B17="","",B17*SUM(Maestro_Ingredientes!$G$7:$G$15)) | D17: =IF(B17="","",B17*SUM(Maestro_Ingredientes!$H$7:$H$15)) | E17: =IF(B17="","",D17-C17) | F17: =IF(B17="","","Introducida")
A18: 46357 | C18: =IF(B18="","",B18*SUM(Maestro_Ingredientes!$G$7:$G$15)) | D18: =IF(B18="","",B18*SUM(Maestro_Ingredientes!$H$7:$H$15)) | E18: =IF(B18="","",D18-C18) | F18: =IF(B18="","","Introducida")
A20: Anual / acumulado
A21: Total de meses informados | B21: =SUM(B7:B18) -> 100000 | C21: =SUM(C7:C18) -> 100000 | D21: =SUM(D7:D18) -> 109651.13 | E21: =SUM(E7:E18) -> 9651.1305
A23: Los meses futuros permanecen en blanco hasta que se introduce la producción. El escenario de 1.200.000 L es solo una referencia.

Sheet Plan_Compras
A2: Plan de compras
A3: Modelo anual para 2026 | EUR | kg y litros
A6: Mes | B6: ID de ingrediente | C6: Ingrediente | D6: Producción planificada L | E6: Necesidad neta kg | F6: Compra requerida kg | G6: Cantidad de compra 1 kg | H6: Precio de compra 1 €/kg | I6: Gasto de compra 1 € | J6: Cantidad de compra 2 kg | K6: Precio de compra 2 €/kg | L6: Gasto de compra 2 € | M6: Cantidad comprada kg | N6: Gasto total € | O6: Precio medio ponderado €/kg | P6: Desviación de compra kg | Q6: Cobertura de compra %
A7: 46023 | B7: ING-001 | C7: =Maestro_Ingredientes!$B$7 -> Tomate pera | D7: =IF(Plan_Produccion!$B$7="","",Plan_Produccion!$B$7) -> 100000 | E7: =IF(D7="","",D7*Maestro_Ingredientes!$G$7) -> 70300 | F7: =IF(D7="","",D7*Maestro_Ingredientes!$H$7) -> 76413.043 | G7: =F7 -> 76413.043 | I7: =IF(OR(G7="",H7=""),"",G7*H7) | L7: =IF(OR(J7="",K7=""),"",J7*K7) | M7: =IF(COUNTA(G7,J7)=0,"",SUM(G7,J7)) -> 76413.043 | N7: =IF(M7="","",IF(OR(AND(G7<>0,H7=""),AND(J7<>0,K7="")),"",SUM(I7,L7))) | O7: =IF(OR(M7="",M7=0,N7=""),"",N7/M7) | P7: =IF(OR(M7="",F7=""),"",M7-F7) -> 0 | Q7: =IF(OR(M7="",F7="",F7=0),"",M7/F7) -> 1
A8: 46023 | B8: ING-002 | C8: =Maestro_Ingredientes!$B$8 -> Pepino | D8: =IF(Plan_Produccion!$B$7="","",Plan_Produccion!$B$7) -> 100000 | E8: =IF(D8="","",D8*Maestro_Ingredientes!$G$8) -> 12200 | F8: =IF(D8="","",D8*Maestro_Ingredientes!$H$8) -> 13863.636 | G8: =F8 -> 13863.636 | I8: =IF(OR(G8="",H8=""),"",G8*H8) | L8: =IF(OR(J8="",K8=""),"",J8*K8) | M8: =IF(COUNTA(G8,J8)=0,"",SUM(G8,J8)) -> 13863.636 | N8: =IF(M8="","",IF(OR(AND(G8<>0,H8=""),AND(J8<>0,K8="")),"",SUM(I8,L8))) | O8: =IF(OR(M8="",M8=0,N8=""),"",N8/M8) | P8: =IF(OR(M8="",F8=""),"",M8-F8) -> 0 | Q8: =IF(OR(M8="",F8="",F8=0),"",M8/F8) -> 1
A9: 46023 | B9: ING-003 | C9: =Maestro_Ingredientes!$B$9 -> Pimiento verde | D9: =IF(Plan_Produccion!$B$7="","",Plan_Produccion!$B$7) -> 100000 | E9: =IF(D9="","",D9*Maestro_Ingredientes!$G$9) -> 7300 | F9: =IF(D9="","",D9*Maestro_Ingredientes!$H$9) -> 8588.2353 | G9: =F9 -> 8588.2353 | I9: =IF(OR(G9="",H9=""),"",G9*H9) | L9: =IF(OR(J9="",K9=""),"",J9*K9) | M9: =IF(COUNTA(G9,J9)=0,"",SUM(G9,J9)) -> 8588.2353 | N9: =IF(M9="","",IF(OR(AND(G9<>0,H9=""),AND(J9<>0,K9="")),"",SUM(I9,L9))) | O9: =IF(OR(M9="",M9=0,N9=""),"",N9/M9) | P9: =IF(OR(M9="",F9=""),"",M9-F9) -> 0 | Q9: =IF(OR(M9="",F9="",F9=0),"",M9/F9) -> 1
A10: 46023 | B10: ING-004 | C10: =Maestro_Ingredientes!$B$10 -> Cebolla | D10: =IF(Plan_Produccion!$B$7="","",Plan_Produccion!$B$7) -> 100000 | E10: =IF(D10="","",D10*Maestro_Ingredientes!$G$10) -> 4400 | F10: =IF(D10="","",D10*Maestro_Ingredientes!$H$10) -> 4888.8889 | G10: =F10 -> 4888.8889 | I10: =IF(OR(G10="",H10=""),"",G10*H10) | L10: =IF(OR(J10="",K10=""),"",J10*K10) | M10: =IF(COUNTA(G10,J10)=0,"",SUM(G10,J10)) -> 4888.8889 | N10: =IF(M10="","",IF(OR(AND(G10<>0,H10=""),AND(J10<>0,K10="")),"",SUM(I10,L10))) | O10: =IF(OR(M10="",M10=0,N10=""),"",N10/M10) | P10: =IF(OR(M10="",F10=""),"",M10-F10) -> 0 | Q10: =IF(OR(M10="",F10="",F10=0),"",M10/F10) -> 1
A11: 46023 | B11: ING-005 | C11: =Maestro_Ingredientes!$B$11 -> Ajo | D11: =IF(Plan_Produccion!$B$7="","",Plan_Produccion!$B$7) -> 100000 | E11: =IF(D11="","",D11*Maestro_Ingredientes!$G$11) -> 800 | F11: =IF(D11="","",D11*Maestro_Ingredientes!$H$11) -> 869.56522 | G11: =F11 -> 869.56522 | I11: =IF(OR(G11="",H11=""),"",G11*H11) | L11: =IF(OR(J11="",K11=""),"",J11*K11) | M11: =IF(COUNTA(G11,J11)=0,"",SUM(G11,J11)) -> 869.56522 | N11: =IF(M11="","",IF(OR(AND(G11<>0,H11=""),AND(J11<>0,K11="")),"",SUM(I11,L11))) | O11: =IF(OR(M11="",M11=0,N11=""),"",N11/M11) | P11: =IF(OR(M11="",F11=""),"",M11-F11) -> 0 | Q11: =IF(OR(M11="",F11="",F11=0),"",M11/F11) -> 1
A12: 46023 | B12: ING-006 | C12: =Maestro_Ingredientes!$B$12 -> Aceite de oliva virgen extra | D12: =IF(Plan_Produccion!$B$7="","",Plan_Produccion!$B$7) -> 100000 | E12: =IF(D12="","",D12*Maestro_Ingredientes!$G$12) -> 2600 | F12: =IF(D12="","",D12*Maestro_Ingredientes!$H$12) -> 2613.0653 | G12: =F12 -> 2613.0653 | I12: =IF(OR(G12="",H12=""),"",G12*H12) | L12: =IF(OR(J12="",K12=""),"",J12*K12) | M12: =IF(COUNTA(G12,J12)=0,"",SUM(G12,J12)) -> 2613.0653 | N12: =IF(M12="","",IF(OR(AND(G12<>0,H12=""),AND(J12<>0,K12="")),"",SUM(I12,L12))) | O12: =IF(OR(M12="",M12=0,N12=""),"",N12/M12) | P12: =IF(OR(M12="",F12=""),"",M12-F12) -> 0 | Q12: =IF(OR(M12="",F12="",F12=0),"",M12/F12) -> 1
A13: 46023 | B13: ING-007 | C13: =Maestro_Ingredientes!$B$13 -> Vinagre de Jerez | D13: =IF(Plan_Produccion!$B$7="","",Plan_Produccion!$B$7) -> 100000 | E13: =IF(D13="","",D13*Maestro_Ingredientes!$G$13) -> 1300 | F13: =IF(D13="","",D13*Maestro_Ingredientes!$H$13) -> 1306.5327 | G13: =F13 -> 1306.5327 | I13: =IF(OR(G13="",H13=""),"",G13*H13) | L13: =IF(OR(J13="",K13=""),"",J13*K13) | M13: =IF(COUNTA(G13,J13)=0,"",SUM(G13,J13)) -> 1306.5327 | N13: =IF(M13="","",IF(OR(AND(G13<>0,H13=""),AND(J13<>0,K13="")),"",SUM(I13,L13))) | O13: =IF(OR(M13="",M13=0,N13=""),"",N13/M13) | P13: =IF(OR(M13="",F13=""),"",M13-F13) -> 0 | Q13: =IF(OR(M13="",F13="",F13=0),"",M13/F13) -> 1
A14: 46023 | B14: ING-008 | C14: =Maestro_Ingredientes!$B$14 -> Sal | D14: =IF(Plan_Produccion!$B$7="","",Plan_Produccion!$B$7) -> 100000 | E14: =IF(D14="","",D14*Maestro_Ingredientes!$G$14) -> 700 | F14: =IF(D14="","",D14*Maestro_Ingredientes!$H$14) -> 700 | G14: =F14 -> 700 | I14: =IF(OR(G14="",H14=""),"",G14*H14) | L14: =IF(OR(J14="",K14=""),"",J14*K14) | M14: =IF(COUNTA(G14,J14)=0,"",SUM(G14,J14)) -> 700 | N14: =IF(M14="","",IF(OR(AND(G14<>0,H14=""),AND(J14<>0,K14="")),"",SUM(I14,L14))) | O14: =IF(OR(M14="",M14=0,N14=""),"",N14/M14) | P14: =IF(OR(M14="",F14=""),"",M14-F14) -> 0 | Q14: =IF(OR(M14="",F14="",F14=0),"",M14/F14) -> 1
A15: 46023 | B15: ING-009 | C15: =Maestro_Ingredientes!$B$15 -> Zumo de limón | D15: =IF(Plan_Produccion!$B$7="","",Plan_Produccion!$B$7) -> 100000 | E15: =IF(D15="","",D15*Maestro_Ingredientes!$G$15) -> 400 | F15: =IF(D15="","",D15*Maestro_Ingredientes!$H$15) -> 408.16327 | G15: =F15 -> 408.16327 | I15: =IF(OR(G15="",H15=""),"",G15*H15) | L15: =IF(OR(J15="",K15=""),"",J15*K15) | M15: =IF(COUNTA(G15,J15)=0,"",SUM(G15,J15)) -> 408.16327 | N15: =IF(M15="","",IF(OR(AND(G15<>0,H15=""),AND(J15<>0,K15="")),"",SUM(I15,L15))) | O15: =IF(OR(M15="",M15=0,N15=""),"",N15/M15) | P15: =IF(OR(M15="",F15=""),"",M15-F15) -> 0 | Q15: =IF(OR(M15="",F15="",F15=0),"",M15/F15) -> 1
A16: 46054 | B16: ING-001 | C16: =Maestro_Ingredientes!$B$7 -> Tomate pera | D16: =IF(Plan_Produccion!$B$8="","",Plan_Produccion!$B$8) | E16: =IF(D16="","",D16*Maestro_Ingredientes!$G$7) | F16: =IF(D16="","",D16*Maestro_Ingredientes!$H$7) | I16: =IF(OR(G16="",H16=""),"",G16*H16) | L16: =IF(OR(J16="",K16=""),"",J16*K16) | M16: =IF(COUNTA(G16,J16)=0,"",SUM(G16,J16)) | N16: =IF(M16="","",IF(OR(AND(G16<>0,H16=""),AND(J16<>0,K16="")),"",SUM(I16,L16))) | O16: =IF(OR(M16="",M16=0,N16=""),"",N16/M16) | P16: =IF(OR(M16="",F16=""),"",M16-F16) | Q16: =IF(OR(M16="",F16="",F16=0),"",M16/F16)
A17: 46054 | B17: ING-002 | C17: =Maestro_Ingredientes!$B$8 -> Pepino | D17: =IF(Plan_Produccion!$B$8="","",Plan_Produccion!$B$8) | E17: =IF(D17="","",D17*Maestro_Ingredientes!$G$8) | F17: =IF(D17="","",D17*Maestro_Ingredientes!$H$8) | I17: =IF(OR(G17="",H17=""),"",G17*H17) | L17: =IF(OR(J17="",K17=""),"",J17*K17) | M17: =IF(COUNTA(G17,J17)=0,"",SUM(G17,J17)) | N17: =IF(M17="","",IF(OR(AND(G17<>0,H17=""),AND(J17<>0,K17="")),"",SUM(I17,L17))) | O17: =IF(OR(M17="",M17=0,N17=""),"",N17/M17) | P17: =IF(OR(M17="",F17=""),"",M17-F17) | Q17: =IF(OR(M17="",F17="",F17=0),"",M17/F17)
A18: 46054 | B18: ING-003 | C18: =Maestro_Ingredientes!$B$9 -> Pimiento verde | D18: =IF(Plan_Produccion!$B$8="","",Plan_Produccion!$B$8) | E18: =IF(D18="","",D18*Maestro_Ingredientes!$G$9) | F18: =IF(D18="","",D18*Maestro_Ingredientes!$H$9) | I18: =IF(OR(G18="",H18=""),"",G18*H18) | L18: =IF(OR(J18="",K18=""),"",J18*K18) | M18: =IF(COUNTA(G18,J18)=0,"",SUM(G18,J18)) | N18: =IF(M18="","",IF(OR(AND(G18<>0,H18=""),AND(J18<>0,K18="")),"",SUM(I18,L18))) | O18: =IF(OR(M18="",M18=0,N18=""),"",N18/M18) | P18: =IF(OR(M18="",F18=""),"",M18-F18) | Q18: =IF(OR(M18="",F18="",F18=0),"",M18/F18)
A19: 46054 | B19: ING-004 | C19: =Maestro_Ingredientes!$B$10 -> Cebolla | D19: =IF(Plan_Produccion!$B$8="","",Plan_Produccion!$B$8) | E19: =IF(D19="","",D19*Maestro_Ingredientes!$G$10) | F19: =IF(D19="","",D19*Maestro_Ingredientes!$H$10) | I19: =IF(OR(G19="",H19=""),"",G19*H19) | L19: =IF(OR(J19="",K19=""),"",J19*K19) | M19: =IF(COUNTA(G19,J19)=0,"",SUM(G19,J19)) | N19: =IF(M19="","",IF(OR(AND(G19<>0,H19=""),AND(J19<>0,K19="")),"",SUM(I19,L19))) | O19: =IF(OR(M19="",M19=0,N19=""),"",N19/M19) | P19: =IF(OR(M19="",F19=""),"",M19-F19) | Q19: =IF(OR(M19="",F19="",F19=0),"",M19/F19)
A20: 46054 | B20: ING-005 | C20: =Maestro_Ingredientes!$B$11 -> Ajo | D20: =IF(Plan_Produccion!$B$8="","",Plan_Produccion!$B$8) | E20: =IF(D20="","",D20*Maestro_Ingredientes!$G$11) | F20: =IF(D20="","",D20*Maestro_Ingredientes!$H$11) | I20: =IF(OR(G20="",H20=""),"",G20*H20) | L20: =IF(OR(J20="",K20=""),"",J20*K20) | M20: =IF(COUNTA(G20,J20)=0,"",SUM(G20,J20)) | N20: =IF(M20="","",IF(OR(AND(G20<>0,H20=""),AND(J20<>0,K20="")),"",SUM(I20,L20))) | O20: =IF(OR(M20="",M20=0,N20=""),"",N20/M20) | P20: =IF(OR(M20="",F20=""),"",M20-F20) | Q20: =IF(OR(M20="",F20="",F20=0),"",M20/F20)
A21: 46054 | B21: ING-006 | C21: =Maestro_Ingredientes!$B$12 -> Aceite de oliva virgen extra | D21: =IF(Plan_Produccion!$B$8="","",Plan_Produccion!$B$8) | E21: =IF(D21="","",D21*Maestro_Ingredientes!$G$12) | F21: =IF(D21="","",D21*Maestro_Ingredientes!$H$12) | I21: =IF(OR(G21="",H21=""),"",G21*H21) | L21: =IF(OR(J21="",K21=""),"",J21*K21) | M21: =IF(COUNTA(G21,J21)=0,"",SUM(G21,J21)) | N21: =IF(M21="","",IF(OR(AND(G21<>0,H21=""),AND(J21<>0,K21="")),"",SUM(I21,L21))) | O21: =IF(OR(M21="",M21=0,N21=""),"",N21/M21) | P21: =IF(OR(M21="",F21=""),"",M21-F21) | Q21: =IF(OR(M21="",F21="",F21=0),"",M21/F21)
A22: 46054 | B22: ING-007 | C22: =Maestro_Ingredientes!$B$13 -> Vinagre de Jerez | D22: =IF(Plan_Produccion!$B$8="","",Plan_Produccion!$B$8) | E22: =IF(D22="","",D22*Maestro_Ingredientes!$G$13) | F22: =IF(D22="","",D22*Maestro_Ingredientes!$H$13) | I22: =IF(OR(G22="",H22=""),"",G22*H22) | L22: =IF(OR(J22="",K22=""),"",J22*K22) | M22: =IF(COUNTA(G22,J22)=0,"",SUM(G22,J22)) | N22: =IF(M22="","",IF(OR(AND(G22<>0,H22=""),AND(J22<>0,K22="")),"",SUM(I22,L22))) | O22: =IF(OR(M22="",M22=0,N22=""),"",N22/M22) | P22: =IF(OR(M22="",F22=""),"",M22-F22) | Q22: =IF(OR(M22="",F22="",F22=0),"",M22/F22)
A23: 46054 | B23: ING-008 | C23: =Maestro_Ingredientes!$B$14 -> Sal | D23: =IF(Plan_Produccion!$B$8="","",Plan_Produccion!$B$8) | E23: =IF(D23="","",D23*Maestro_Ingredientes!$G$14) | F23: =IF(D23="","",D23*Maestro_Ingredientes!$H$14) | I23: =IF(OR(G23="",H23=""),"",G23*H23) | L23: =IF(OR(J23="",K23=""),"",J23*K23) | M23: =IF(COUNTA(G23,J23)=0,"",SUM(G23,J23)) | N23: =IF(M23="","",IF(OR(AND(G23<>0,H23=""),AND(J23<>0,K23="")),"",SUM(I23,L23))) | O23: =IF(OR(M23="",M23=0,N23=""),"",N23/M23) | P23: =IF(OR(M23="",F23=""),"",M23-F23) | Q23: =IF(OR(M23="",F23="",F23=0),"",M23/F23)
A24: 46054 | B24: ING-009 | C24: =Maestro_Ingredientes!$B$15 -> Zumo de limón | D24: =IF(Plan_Produccion!$B$8="","",Plan_Produccion!$B$8) | E24: =IF(D24="","",D24*Maestro_Ingredientes!$G$15) | F24: =IF(D24="","",D24*Maestro_Ingredientes!$H$15) | I24: =IF(OR(G24="",H24=""),"",G24*H24) | L24: =IF(OR(J24="",K24=""),"",J24*K24) | M24: =IF(COUNTA(G24,J24)=0,"",SUM(G24,J24)) | N24: =IF(M24="","",IF(OR(AND(G24<>0,H24=""),AND(J24<>0,K24="")),"",SUM(I24,L24))) | O24: =IF(OR(M24="",M24=0,N24=""),"",N24/M24) | P24: =IF(OR(M24="",F24=""),"",M24-F24) | Q24: =IF(OR(M24="",F24="",F24=0),"",M24/F24)
A25: 46082 | B25: ING-001 | C25: =Maestro_Ingredientes!$B$7 -> Tomate pera | D25: =IF(Plan_Produccion!$B$9="","",Plan_Produccion!$B$9) | E25: =IF(D25="","",D25*Maestro_Ingredientes!$G$7) | F25: =IF(D25="","",D25*Maestro_Ingredientes!$H$7) | I25: =IF(OR(G25="",H25=""),"",G25*H25) | L25: =IF(OR(J25="",K25=""),"",J25*K25) | M25: =IF(COUNTA(G25,J25)=0,"",SUM(G25,J25)) | N25: =IF(M25="","",IF(OR(AND(G25<>0,H25=""),AND(J25<>0,K25="")),"",SUM(I25,L25))) | O25: =IF(OR(M25="",M25=0,N25=""),"",N25/M25) | P25: =IF(OR(M25="",F25=""),"",M25-F25) | Q25: =IF(OR(M25="",F25="",F25=0),"",M25/F25)
A26: 46082 | B26: ING-002 | C26: =Maestro_Ingredientes!$B$8 -> Pepino | D26: =IF(Plan_Produccion!$B$9="","",Plan_Produccion!$B$9) | E26: =IF(D26="","",D26*Maestro_Ingredientes!$G$8) | F26: =IF(D26="","",D26*Maestro_Ingredientes!$H$8) | I26: =IF(OR(G26="",H26=""),"",G26*H26) | L26: =IF(OR(J26="",K26=""),"",J26*K26) | M26: =IF(COUNTA(G26,J26)=0,"",SUM(G26,J26)) | N26: =IF(M26="","",IF(OR(AND(G26<>0,H26=""),AND(J26<>0,K26="")),"",SUM(I26,L26))) | O26: =IF(OR(M26="",M26=0,N26=""),"",N26/M26) | P26: =IF(OR(M26="",F26=""),"",M26-F26) | Q26: =IF(OR(M26="",F26="",F26=0),"",M26/F26)
A27: 46082 | B27: ING-003 | C27: =Maestro_Ingredientes!$B$9 -> Pimiento verde | D27: =IF(Plan_Produccion!$B$9="","",Plan_Produccion!$B$9) | E27: =IF(D27="","",D27*Maestro_Ingredientes!$G$9) | F27: =IF(D27="","",D27*Maestro_Ingredientes!$H$9) | I27: =IF(OR(G27="",H27=""),"",G27*H27) | L27: =IF(OR(J27="",K27=""),"",J27*K27) | M27: =IF(COUNTA(G27,J27)=0,"",SUM(G27,J27)) | N27: =IF(M27="","",IF(OR(AND(G27<>0,H27=""),AND(J27<>0,K27="")),"",SUM(I27,L27))) | O27: =IF(OR(M27="",M27=0,N27=""),"",N27/M27) | P27: =IF(OR(M27="",F27=""),"",M27-F27) | Q27: =IF(OR(M27="",F27="",F27=0),"",M27/F27)
A28: 46082 | B28: ING-004 | C28: =Maestro_Ingredientes!$B$10 -> Cebolla | D28: =IF(Plan_Produccion!$B$9="","",Plan_Produccion!$B$9) | E28: =IF(D28="","",D28*Maestro_Ingredientes!$G$10) | F28: =IF(D28="","",D28*Maestro_Ingredientes!$H$10) | I28: =IF(OR(G28="",H28=""),"",G28*H28) | L28: =IF(OR(J28="",K28=""),"",J28*K28) | M28: =IF(COUNTA(G28,J28)=0,"",SUM(G28,J28)) | N28: =IF(M28="","",IF(OR(AND(G28<>0,H28=""),AND(J28<>0,K28="")),"",SUM(I28,L28))) | O28: =IF(OR(M28="",M28=0,N28=""),"",N28/M28) | P28: =IF(OR(M28="",F28=""),"",M28-F28) | Q28: =IF(OR(M28="",F28="",F28=0),"",M28/F28)
A29: 46082 | B29: ING-005 | C29: =Maestro_Ingredientes!$B$11 -> Ajo | D29: =IF(Plan_Produccion!$B$9="","",Plan_Produccion!$B$9) | E29: =IF(D29="","",D29*Maestro_Ingredientes!$G$11) | F29: =IF(D29="","",D29*Maestro_Ingredientes!$H$11) | I29: =IF(OR(G29="",H29=""),"",G29*H29) | L29: =IF(OR(J29="",K29=""),"",J29*K29) | M29: =IF(COUNTA(G29,J29)=0,"",SUM(G29,J29)) | N29: =IF(M29="","",IF(OR(AND(G29<>0,H29=""),AND(J29<>0,K29="")),"",SUM(I29,L29))) | O29: =IF(OR(M29="",M29=0,N29=""),"",N29/M29) | P29: =IF(OR(M29="",F29=""),"",M29-F29) | Q29: =IF(OR(M29="",F29="",F29=0),"",M29/F29)
A30: 46082 | B30: ING-006 | C30: =Maestro_Ingredientes!$B$12 -> Aceite de oliva virgen extra | D30: =IF(Plan_Produccion!$B$9="","",Plan_Produccion!$B$9) | E30: =IF(D30="","",D30*Maestro_Ingredientes!$G$12) | F30: =IF(D30="","",D30*Maestro_Ingredientes!$H$12) | I30: =IF(OR(G30="",H30=""),"",G30*H30) | L30: =IF(OR(J30="",K30=""),"",J30*K30) | M30: =IF(COUNTA(G30,J30)=0,"",SUM(G30,J30)) | N30: =IF(M30="","",IF(OR(AND(G30<>0,H30=""),AND(J30<>0,K30="")),"",SUM(I30,L30))) | O30: =IF(OR(M30="",M30=0,N30=""),"",N30/M30) | P30: =IF(OR(M30="",F30=""),"",M30-F30) | Q30: =IF(OR(M30="",F30="",F30=0),"",M30/F30)
A31: 46082 | B31: ING-007 | C31: =Maestro_Ingredientes!$B$13 -> Vinagre de Jerez | D31: =IF(Plan_Produccion!$B$9="","",Plan_Produccion!$B$9) | E31: =IF(D31="","",D31*Maestro_Ingredientes!$G$13) | F31: =IF(D31="","",D31*Maestro_Ingredientes!$H$13) | I31: =IF(OR(G31="",H31=""),"",G31*H31) | L31: =IF(OR(J31="",K31=""),"",J31*K31) | M31: =IF(COUNTA(G31,J31)=0,"",SUM(G31,J31)) | N31: =IF(M31="","",IF(OR(AND(G31<>0,H31=""),AND(J31<>0,K31="")),"",SUM(I31,L31))) | O31: =IF(OR(M31="",M31=0,N31=""),"",N31/M31) | P31: =IF(OR(M31="",F31=""),"",M31-F31) | Q31: =IF(OR(M31="",F31="",F31=0),"",M31/F31)
A32: 46082 | B32: ING-008 | C32: =Maestro_Ingredientes!$B$14 -> Sal | D32: =IF(Plan_Produccion!$B$9="","",Plan_Produccion!$B$9) | E32: =IF(D32="","",D32*Maestro_Ingredientes!$G$14) | F32: =IF(D32="","",D32*Maestro_Ingredientes!$H$14) | I32: =IF(OR(G32="",H32=""),"",G32*H32) | L32: =IF(OR(J32="",K32=""),"",J32*K32) | M32: =IF(COUNTA(G32,J32)=0,"",SUM(G32,J32)) | N32: =IF(M32="","",IF(OR(AND(G32<>0,H32=""),AND(J32<>0,K32="")),"",SUM(I32,L32))) | O32: =IF(OR(M32="",M32=0,N32=""),"",N32/M32) | P32: =IF(OR(M32="",F32=""),"",M32-F32) | Q32: =IF(OR(M32="",F32="",F32=0),"",M32/F32)
A33: 46082 | B33: ING-009 | C33: =Maestro_Ingredientes!$B$15 -> Zumo de limón | D33: =IF(Plan_Produccion!$B$9="","",Plan_Produccion!$B$9) | E33: =IF(D33="","",D33*Maestro_Ingredientes!$G$15) | F33: =IF(D33="","",D33*Maestro_Ingredientes!$H$15) | I33: =IF(OR(G33="",H33=""),"",G33*H33) | L33: =IF(OR(J33="",K33=""),"",J33*K33) | M33: =IF(COUNTA(G33,J33)=0,"",SUM(G33,J33)) | N33: =IF(M33="","",IF(OR(AND(G33<>0,H33=""),AND(J33<>0,K33="")),"",SUM(I33,L33))) | O33: =IF(OR(M33="",M33=0,N33=""),"",N33/M33) | P33: =IF(OR(M33="",F33=""),"",M33-F33) | Q33: =IF(OR(M33="",F33="",F33=0),"",M33/F33)
A34: 46113 | B34: ING-001 | C34: =Maestro_Ingredientes!$B$7 -> Tomate pera | D34: =IF(Plan_Produccion!$B$10="","",Plan_Produccion!$B$10) | E34: =IF(D34="","",D34*Maestro_Ingredientes!$G$7) | F34: =IF(D34="","",D34*Maestro_Ingredientes!$H$7) | I34: =IF(OR(G34="",H34=""),"",G34*H34) | L34: =IF(OR(J34="",K34=""),"",J34*K34) | M34: =IF(COUNTA(G34,J34)=0,"",SUM(G34,J34)) | N34: =IF(M34="","",IF(OR(AND(G34<>0,H34=""),AND(J34<>0,K34="")),"",SUM(I34,L34))) | O34: =IF(OR(M34="",M34=0,N34=""),"",N34/M34) | P34: =IF(OR(M34="",F34=""),"",M34-F34) | Q34: =IF(OR(M34="",F34="",F34=0),"",M34/F34)
A35: 46113 | B35: ING-002 | C35: =Maestro_Ingredientes!$B$8 -> Pepino | D35: =IF(Plan_Produccion!$B$10="","",Plan_Produccion!$B$10) | E35: =IF(D35="","",D35*Maestro_Ingredientes!$G$8) | F35: =IF(D35="","",D35*Maestro_Ingredientes!$H$8) | I35: =IF(OR(G35="",H35=""),"",G35*H35) | L35: =IF(OR(J35="",K35=""),"",J35*K35) | M35: =IF(COUNTA(G35,J35)=0,"",SUM(G35,J35)) | N35: =IF(M35="","",IF(OR(AND(G35<>0,H35=""),AND(J35<>0,K35="")),"",SUM(I35,L35))) | O35: =IF(OR(M35="",M35=0,N35=""),"",N35/M35) | P35: =IF(OR(M35="",F35=""),"",M35-F35) | Q35: =IF(OR(M35="",F35="",F35=0),"",M35/F35)
A36: 46113 | B36: ING-003 | C36: =Maestro_Ingredientes!$B$9 -> Pimiento verde | D36: =IF(Plan_Produccion!$B$10="","",Plan_Produccion!$B$10) | E36: =IF(D36="","",D36*Maestro_Ingredientes!$G$9) | F36: =IF(D36="","",D36*Maestro_Ingredientes!$H$9) | I36: =IF(OR(G36="",H36=""),"",G36*H36) | L36: =IF(OR(J36="",K36=""),"",J36*K36) | M36: =IF(COUNTA(G36,J36)=0,"",SUM(G36,J36)) | N36: =IF(M36="","",IF(OR(AND(G36<>0,H36=""),AND(J36<>0,K36="")),"",SUM(I36,L36))) | O36: =IF(OR(M36="",M36=0,N36=""),"",N36/M36) | P36: =IF(OR(M36="",F36=""),"",M36-F36) | Q36: =IF(OR(M36="",F36="",F36=0),"",M36/F36)
A37: 46113 | B37: ING-004 | C37: =Maestro_Ingredientes!$B$10 -> Cebolla | D37: =IF(Plan_Produccion!$B$10="","",Plan_Produccion!$B$10) | E37: =IF(D37="","",D37*Maestro_Ingredientes!$G$10) | F37: =IF(D37="","",D37*Maestro_Ingredientes!$H$10) | I37: =IF(OR(G37="",H37=""),"",G37*H37) | L37: =IF(OR(J37="",K37=""),"",J37*K37) | M37: =IF(COUNTA(G37,J37)=0,"",SUM(G37,J37)) | N37: =IF(M37="","",IF(OR(AND(G37<>0,H37=""),AND(J37<>0,K37="")),"",SUM(I37,L37))) | O37: =IF(OR(M37="",M37=0,N37=""),"",N37/M37) | P37: =IF(OR(M37="",F37=""),"",M37-F37) | Q37: =IF(OR(M37="",F37="",F37=0),"",M37/F37)
A38: 46113 | B38: ING-005 | C38: =Maestro_Ingredientes!$B$11 -> Ajo | D38: =IF(Plan_Produccion!$B$10="","",Plan_Produccion!$B$10) | E38: =IF(D38="","",D38*Maestro_Ingredientes!$G$11) | F38: =IF(D38="","",D38*Maestro_Ingredientes!$H$11) | I38: =IF(OR(G38="",H38=""),"",G38*H38) | L38: =IF(OR(J38="",K38=""),"",J38*K38) | M38: =IF(COUNTA(G38,J38)=0,"",SUM(G38,J38)) | N38: =IF(M38="","",IF(OR(AND(G38<>0,H38=""),AND(J38<>0,K38="")),"",SUM(I38,L38))) | O38: =IF(OR(M38="",M38=0,N38=""),"",N38/M38) | P38: =IF(OR(M38="",F38=""),"",M38-F38) | Q38: =IF(OR(M38="",F38="",F38=0),"",M38/F38)
A39: 46113 | B39: ING-006 | C39: =Maestro_Ingredientes!$B$12 -> Aceite de oliva virgen extra | D39: =IF(Plan_Produccion!$B$10="","",Plan_Produccion!$B$10) | E39: =IF(D39="","",D39*Maestro_Ingredientes!$G$12) | F39: =IF(D39="","",D39*Maestro_Ingredientes!$H$12) | I39: =IF(OR(G39="",H39=""),"",G39*H39) | L39: =IF(OR(J39="",K39=""),"",J39*K39) | M39: =IF(COUNTA(G39,J39)=0,"",SUM(G39,J39)) | N39: =IF(M39="","",IF(OR(AND(G39<>0,H39=""),AND(J39<>0,K39="")),"",SUM(I39,L39))) | O39: =IF(OR(M39="",M39=0,N39=""),"",N39/M39) | P39: =IF(OR(M39="",F39=""),"",M39-F39) | Q39: =IF(OR(M39="",F39="",F39=0),"",M39/F39)
A40: 46113 | B40: ING-007 | C40: =Maestro_Ingredientes!$B$13 -> Vinagre de Jerez | D40: =IF(Plan_Produccion!$B$10="","",Plan_Produccion!$B$10) | E40: =IF(D40="","",D40*Maestro_Ingredientes!$G$13) | F40: =IF(D40="","",D40*Maestro_Ingredientes!$H$13) | I40: =IF(OR(G40="",H40=""),"",G40*H40) | L40: =IF(OR(J40="",K40=""),"",J40*K40) | M40: =IF(COUNTA(G40,J40)=0,"",SUM(G40,J40)) | N40: =IF(M40="","",IF(OR(AND(G40<>0,H40=""),AND(J40<>0,K40="")),"",SUM(I40,L40))) | O40: =IF(OR(M40="",M40=0,N40=""),"",N40/M40) | P40: =IF(OR(M40="",F40=""),"",M40-F40) | Q40: =IF(OR(M40="",F40="",F40=0),"",M40/F40)
A41: 46113 | B41: ING-008 | C41: =Maestro_Ingredientes!$B$14 -> Sal | D41: =IF(Plan_Produccion!$B$10="","",Plan_Produccion!$B$10) | E41: =IF(D41="","",D41*Maestro_Ingredientes!$G$14) | F41: =IF(D41="","",D41*Maestro_Ingredientes!$H$14) | I41: =IF(OR(G41="",H41=""),"",G41*H41) | L41: =IF(OR(J41="",K41=""),"",J41*K41) | M41: =IF(COUNTA(G41,J41)=0,"",SUM(G41,J41)) | N41: =IF(M41="","",IF(OR(AND(G41<>0,H41=""),AND(J41<>0,K41="")),"",SUM(I41,L41))) | O41: =IF(OR(M41="",M41=0,N41=""),"",N41/M41) | P41: =IF(OR(M41="",F41=""),"",M41-F41) | Q41: =IF(OR(M41="",F41="",F41=0),"",M41/F41)
A42: 46113 | B42: ING-009 | C42: =Maestro_Ingredientes!$B$15 -> Zumo de limón | D42: =IF(Plan_Produccion!$B$10="","",Plan_Produccion!$B$10) | E42: =IF(D42="","",D42*Maestro_Ingredientes!$G$15) | F42: =IF(D42="","",D42*Maestro_Ingredientes!$H$15) | I42: =IF(OR(G42="",H42=""),"",G42*H42) | L42: =IF(OR(J42="",K42=""),"",J42*K42) | M42: =IF(COUNTA(G42,J42)=0,"",SUM(G42,J42)) | N42: =IF(M42="","",IF(OR(AND(G42<>0,H42=""),AND(J42<>0,K42="")),"",SUM(I42,L42))) | O42: =IF(OR(M42="",M42=0,N42=""),"",N42/M42) | P42: =IF(OR(M42="",F42=""),"",M42-F42) | Q42: =IF(OR(M42="",F42="",F42=0),"",M42/F42)
A43: 46143 | B43: ING-001 | C43: =Maestro_Ingredientes!$B$7 -> Tomate pera | D43: =IF(Plan_Produccion!$B$11="","",Plan_Produccion!$B$11) | E43: =IF(D43="","",D43*Maestro_Ingredientes!$G$7) | F43: =IF(D43="","",D43*Maestro_Ingredientes!$H$7) | I43: =IF(OR(G43="",H43=""),"",G43*H43) | L43: =IF(OR(J43="",K43=""),"",J43*K43) | M43: =IF(COUNTA(G43,J43)=0,"",SUM(G43,J43)) | N43: =IF(M43="","",IF(OR(AND(G43<>0,H43=""),AND(J43<>0,K43="")),"",SUM(I43,L43))) | O43: =IF(OR(M43="",M43=0,N43=""),"",N43/M43) | P43: =IF(OR(M43="",F43=""),"",M43-F43) | Q43: =IF(OR(M43="",F43="",F43=0),"",M43/F43)
...

Sheet Modelo_Costes
A2: Modelo de costes y KPI
A3: Modelo anual para 2026 | EUR | kg y litros
A6: KPI anuales / acumulados | R6: Los gráficos se completan después de introducir los precios de compra.
A8: Producción planificada / registrada acumulada | B8: =SUM(Plan_Produccion!$B$7:$B$18) -> 100000 | D8: Definición | E8: Valor
A9: Necesidad neta de materia prima | B9: =SUM(Plan_Produccion!$C$7:$C$18) -> 100000 | D9: Año del modelo | E9: =Supuestos!$B$7 -> 2026
A10: Necesidad bruta de materia prima | B10: =SUM(Plan_Produccion!$D$7:$D$18) -> 109651.13 | D10: Escenario anual de referencia L | E10: =Supuestos!$B$8 -> 1200000
A11: Materia prima comprada | B11: =SUM(Plan_Compras!$M$7:$M$114) -> 109651.13 | D11: Umbral de alerta de merma | E11: =Supuestos!$B$13 -> 0.01
A12: Merma esperada kg | B12: =SUM(Plan_Produccion!$E$7:$E$18) -> 9651.1305 | D12: Control de receta | E12: =Maestro_Ingredientes!$B$21 -> OK
A13: Merma real kg | B13: =IF(COUNT($F$50:$F$61)=0,"",SUM($F$50:$F$61))
A14: Rendimiento de materia prima % | B14: =IF(B10=0,"",B9/B10) -> 0.9119833
A15: Gasto total de materia prima € | B15: =IF(COUNT(Plan_Compras!$N$7:$N$114)=0,"",SUM(Plan_Compras!$N$7:$N$114))
A16: Cobertura de compra % | B16: =IF(B10=0,"",B11/B10) -> 1
A17: Mayor desviación de compra | B17: =IF(COUNT(Plan_Compras!$P$7:$P$114)=0,"",CHOOSE(MONTH(INDEX(Plan_Compras!$A$7:$A$114,MATCH(IF(MAX(Plan_Compras!$P$7:$P$114)>=-MIN(Plan_Compras!$P$7:$P$114),MAX(Plan_Compras!$P$7:$P$114),MIN(Plan_Compras!$P$7:$P$114)),Plan_Compras!$P$7:$P$114,0))),"Enero","Febrero","Marzo","Abril","Mayo","Junio","Julio","Agosto","Septiembre","Octubre","Noviembre","Diciembre")&" | "&INDEX(Plan_Compras!$C$7:$C$114,MATCH(IF(MAX(Plan_Compras!$P$7:$P$114)>=-MIN(Plan_Compras!$P$7:$P$114),MAX(Plan_Compras!$P$7:$P$114),MIN(Plan_Compras!$P$7:$P$114)),Plan_Compras!$P$7:$P$114,0))&" | "&TEXT(IF(MAX(Plan_Compras!$P$7:$P$114)>=-MIN(Plan_Compras!$P$7:$P$114),MAX(Plan_Compras!$P$7:$P$114),MIN(Plan_Compras!$P$7:$P$114)),"+#,##0;-#,##0;+0")&" kg") -> Enero | Tomate pera | +0 kg
A18: Ingrediente con mayor coste | B18: =IF(COUNT($D$67:$D$75)=0,"",INDEX($A$67:$A$75,MATCH(MAX($D$67:$D$75),$D$67:$D$75,0)))
A19: Coste de materia prima €/L | B19: =IF(OR(B8=0,B15=""),"",B15/B8)
A20: Coste total de producto €/L | B20: =IF(SUMPRODUCT(--ISNUMBER($O$50:$O$61),$B$50:$B$61)=0,"",SUMPRODUCT($O$50:$O$61,$B$50:$B$61)/SUMPRODUCT(--ISNUMBER($O$50:$O$61),$B$50:$B$61))
A21: Coste estimado de merma € | B21: =IF(COUNT($K$67:$K$75)=0,"",SUM($K$67:$K$75))
A22: Coste de merma % del gasto de materia prima | B22: =IF(OR(NOT(ISNUMBER(B21)),NOT(ISNUMBER(B15)),B15=0),"",B21/B15)
A23: Merma esperada acumulada (meses informados) | B23: =IF(COUNT($F$50:$F$61)=0,"",SUMIF($F$50:$F$61,">=0",$E$50:$E$61))
A24: Merma real acumulada | B24: =IF(COUNT($F$50:$F$61)=0,"",SUM($F$50:$F$61))
A25: Desviación de merma acumulada | B25: =IF(OR(B23="",B24=""),"",B24-B23)
A26: Meses con alertas de merma | B26: =COUNTIF($P$50:$P$61,"ALERTA*") -> 0
A27: Precisión de la estimación de merma | B27: =IF(OR(B23="",B23=0,B25=""),"",MAX(0,1-ABS(B25)/B23))
A30: KPI mensuales
A32: Métrica | B32: Ene | C32: Feb | D32: Mar | E32: Abr | F32: May | G32: Jun | H32: Jul | I32: Ago | J32: Sep | K32: Oct | L32: Nov | M32: Dic | N32: Acumulado
A33: Volumen de producto terminado L | B33: =IF($B$50="","",$B$50) -> 100000 | C33: =IF($B$51="","",$B$51) | D33: =IF($B$52="","",$B$52) | E33: =IF($B$53="","",$B$53) | F33: =IF($B$54="","",$B$54) | G33: =IF($B$55="","",$B$55) | H33: =IF($B$56="","",$B$56) | I33: =IF($B$57="","",$B$57) | J33: =IF($B$58="","",$B$58) | K33: =IF($B$59="","",$B$59) | L33: =IF($B$60="","",$B$60) | M33: =IF($B$61="","",$B$61) | N33: =B8 -> 100000
A34: Materia prima requerida kg | B34: =IF($C$50="","",$C$50) -> 109651.13 | C34: =IF($C$51="","",$C$51) | D34: =IF($C$52="","",$C$52) | E34: =IF($C$53="","",$C$53) | F34: =IF($C$54="","",$C$54) | G34: =IF($C$55="","",$C$55) | H34: =IF($C$56="","",$C$56) | I34: =IF($C$57="","",$C$57) | J34: =IF($C$58="","",$C$58) | K34: =IF($C$59="","",$C$59) | L34: =IF($C$60="","",$C$60) | M34: =IF($C$61="","",$C$61) | N34: =B10 -> 109651.13
A35: Materia prima comprada kg | B35: =IF($D$50="","",$D$50) -> 109651.13 | C35: =IF($D$51="","",$D$51) | D35: =IF($D$52="","",$D$52) | E35: =IF($D$53="","",$D$53) | F35: =IF($D$54="","",$D$54) | G35: =IF($D$55="","",$D$55) | H35: =IF($D$56="","",$D$56) | I35: =IF($D$57="","",$D$57) | J35: =IF($D$58="","",$D$58) | K35: =IF($D$59="","",$D$59) | L35: =IF($D$60="","",$D$60) | M35: =IF($D$61="","",$D$61) | N35: =B11 -> 109651.13
A36: Cobertura de compra % | B36: =IF(OR($C$50="",$C$50=0,$D$50=""),"",$D$50/$C$50) -> 1 | C36: =IF(OR($C$51="",$C$51=0,$D$51=""),"",$D$51/$C$51) | D36: =IF(OR($C$52="",$C$52=0,$D$52=""),"",$D$52/$C$52) | E36: =IF(OR($C$53="",$C$53=0,$D$53=""),"",$D$53/$C$53) | F36: =IF(OR($C$54="",$C$54=0,$D$54=""),"",$D$54/$C$54) | G36: =IF(OR($C$55="",$C$55=0,$D$55=""),"",$D$55/$C$55) | H36: =IF(OR($C$56="",$C$56=0,$D$56=""),"",$D$56/$C$56) | I36: =IF(OR($C$57="",$C$57=0,$D$57=""),"",$D$57/$C$57) | J36: =IF(OR($C$58="",$C$58=0,$D$58=""),"",$D$58/$C$58) | K36: =IF(OR($C$59="",$C$59=0,$D$59=""),"",$D$59/$C$59) | L36: =IF(OR($C$60="",$C$60=0,$D$60=""),"",$D$60/$C$60) | M36: =IF(OR($C$61="",$C$61=0,$D$61=""),"",$D$61/$C$61) | N36: =B16 -> 1
A37: Gasto de materia prima € | B37: =IF($J$50="","",$J$50) | C37: =IF($J$51="","",$J$51) | D37: =IF($J$52="","",$J$52) | E37: =IF($J$53="","",$J$53) | F37: =IF($J$54="","",$J$54) | G37: =IF($J$55="","",$J$55) | H37: =IF($J$56="","",$J$56) | I37: =IF($J$57="","",$J$57) | J37: =IF($J$58="","",$J$58) | K37: =IF($J$59="","",$J$59) | L37: =IF($J$60="","",$J$60) | M37: =IF($J$61="","",$J$61) | N37: =IF(B15="","",B15)
A38: Coste de materia prima €/L | B38: =IF($K$50="","",$K$50) | C38: =IF($K$51="","",$K$51) | D38: =IF($K$52="","",$K$52) | E38: =IF($K$53="","",$K$53) | F38: =IF($K$54="","",$K$54) | G38: =IF($K$55="","",$K$55) | H38: =IF($K$56="","",$K$56) | I38: =IF($K$57="","",$K$57) | J38: =IF($K$58="","",$K$58) | K38: =IF($K$59="","",$K$59) | L38: =IF($K$60="","",$K$60) | M38: =IF($K$61="","",$K$61) | N38: =IF(B19="","",B19)
A39: Coste total de producto €/L | B39: =IF($O$50="","",$O$50) | C39: =IF($O$51="","",$O$51) | D39: =IF($O$52="","",$O$52) | E39: =IF($O$53="","",$O$53) | F39: =IF($O$54="","",$O$54) | G39: =IF($O$55="","",$O$55) | H39: =IF($O$56="","",$O$56) | I39: =IF($O$57="","",$O$57) | J39: =IF($O$58="","",$O$58) | K39: =IF($O$59="","",$O$59) | L39: =IF($O$60="","",$O$60) | M39: =IF($O$61="","",$O$61) | N39: =IF(B20="","",B20)
A40: Merma esperada kg | B40: =IF($E$50="","",$E$50) -> 9651.1305 | C40: =IF($E$51="","",$E$51) | D40: =IF($E$52="","",$E$52) | E40: =IF($E$53="","",$E$53) | F40: =IF($E$54="","",$E$54) | G40: =IF($E$55="","",$E$55) | H40: =IF($E$56="","",$E$56) | I40: =IF($E$57="","",$E$57) | J40: =IF($E$58="","",$E$58) | K40: =IF($E$59="","",$E$59) | L40: =IF($E$60="","",$E$60) | M40: =IF($E$61="","",$E$61) | N40: =B12 -> 9651.1305
A41: Merma real kg | B41: =IF($F$50="","",$F$50) | C41: =IF($F$51="","",$F$51) | D41: =IF($F$52="","",$F$52) | E41: =IF($F$53="","",$F$53) | F41: =IF($F$54="","",$F$54) | G41: =IF($F$55="","",$F$55) | H41: =IF($F$56="","",$F$56) | I41: =IF($F$57="","",$F$57) | J41: =IF($F$58="","",$F$58) | K41: =IF($F$59="","",$F$59) | L41: =IF($F$60="","",$F$60) | M41: =IF($F$61="","",$F$61) | N41: =IF(B24="","",B24)
A42: Desviación de merma kg | B42: =IF($G$50="","",$G$50) | C42: =IF($G$51="","",$G$51) | D42: =IF($G$52="","",$G$52) | E42: =IF($G$53="","",$G$53) | F42: =IF($G$54="","",$G$54) | G42: =IF($G$55="","",$G$55) | H42: =IF($G$56="","",$G$56) | I42: =IF($G$57="","",$G$57) | J42: =IF($G$58="","",$G$58) | K42: =IF($G$59="","",$G$59) | L42: =IF($G$60="","",$G$60) | M42: =IF($G$61="","",$G$61) | N42: =IF(B25="","",B25)
A43: Desviación de merma % de la producción | B43: =IF($H$50="","",$H$50) | C43: =IF($H$51="","",$H$51) | D43: =IF($H$52="","",$H$52) | E43: =IF($H$53="","",$H$53) | F43: =IF($H$54="","",$H$54) | G43: =IF($H$55="","",$H$55) | H43: =IF($H$56="","",$H$56) | I43: =IF($H$57="","",$H$57) | J43: =IF($H$58="","",$H$58) | K43: =IF($H$59="","",$H$59) | L43: =IF($H$60="","",$H$60) | M43: =IF($H$61="","",$H$61) | N43: =IF(OR(B8=0,B25=""),"",B25/B8)
A44: Estado del control de merma | B44: =IF($P$50="","",$P$50) | C44: =IF($P$51="","",$P$51) | D44: =IF($P$52="","",$P$52) | E44: =IF($P$53="","",$P$53) | F44: =IF($P$54="","",$P$54) | G44: =IF($P$55="","",$P$55) | H44: =IF($P$56="","",$P$56) | I44: =IF($P$57="","",$P$57) | J44: =IF($P$58="","",$P$58) | K44: =IF($P$59="","",$P$59) | L44: =IF($P$60="","",$P$60) | M44: =IF($P$61="","",$P$61)
A47: Modelo mensual de costes y merma
A49: Mes | B49: Producción terminada L | C49: Materia prima requerida kg | D49: Materia prima comprada kg | E49: Merma esperada kg | F49: Merma real kg | G49: Desviación de merma kg | H49: Desviación de merma % de la producción | I49: Precisión de la estimación de merma | J49: Gasto de materia prima € | K49: Coste de materia prima €/L | L49: Coste variable de fabricación €/L | M49: Coste de envasado €/L | N49: Otros costes variables €/L | O49: Coste total de producto €/L | P49: Estado del control de merma
A50: Ene | B50: =IF(Plan_Produccion!$B$7="","",Plan_Produccion!$B$7) -> 100000 | C50: =IF(B50="","",Plan_Produccion!$D$7) -> 109651.13 | D50: =IF(B50="","",IF(COUNT(Plan_Compras!$M$7:$M$15)=0,"",SUM(Plan_Compras!$M$7:$M$15))) -> 109651.13 | E50: =IF(B50="","",Plan_Produccion!$E$7) -> 9651.1305 | G50: =IF(F50="","",F50-E50) | H50: =IF(OR(F50="",B50="",B50=0),"",G50/B50) | I50: =IF(OR(F50="",E50="",E50=0),"",MAX(0,1-ABS(G50)/E50)) | J50: =IF(B50="","",IF(COUNT(Plan_Compras!$N$7:$N$15)=0,"",SUM(Plan_Compras!$N$7:$N$15))) | K50: =IF(OR(J50="",B50="",B50=0),"",J50/B50) | O50: =IF(OR(K50="",L50="",M50="",N50=""),"",SUM(K50:N50)) | P50: =IF(OR(F50="",H50=""),"",IF(ABS(H50)<=Supuestos!$B$13,"OK",IF(H50>Supuestos!$B$13,"ALERTA – MERMA SUPERIOR A LA ESPERADA","ALERTA – MERMA INFERIOR A LA ESPERADA")))
...
